Workbook

Sheet quarterly
B1: Non_oil_GDP | C1: Private_consumption | D1: Total_FBKF | E1: Oil_GDP | F1: Gov_consumption | G1: World_GDP_growth_qoq | H1: Oil_GDP_real | I1: Trade_balance | J1: GDP | K1: US_Y_Deflator | L1: Gov_investment | M1: Gov_transfers_with_ss | N1: Gov_transfers_no_ss | O1: Hours | P1: EC_Y_Deflator | Q1: Unemployment | R1: Gov_Debt | S1: D_Gov_Debt
A2: 2000.I | B2: =oilGDPnominal!C10 -> 3290847 | C2: =consumption_investment_governme!F10 -> 2445053 | D2: =consumption_investment_governme!H10 -> 723232 | E2: =oilGDPnominal!B10 -> 332388 | F2: 175154 | G2: =worldGDP!AU214 -> 0.98529 | H2: =oilGDPreal!B9 -> 1218387 | I2: 386080 | J2: 3819126 | K2: =US_GDP_deflator!B224 -> 77.396 | L2: 148.45286 | P2: 41.80951
A3: 2000.II | B3: =oilGDPnominal!C11 -> 3806141 | C3: =consumption_investment_governme!F11 -> 2841942 | D3: =consumption_investment_governme!H11 -> 821301 | E3: =oilGDPnominal!B11 -> 369840 | F3: 389776 | G3: =worldGDP!AU215 -> 1.245711 | H3: =oilGDPreal!B10 -> 1191946 | I3: 308601 | J3: 4402479 | K3: =US_GDP_deflator!B225 -> 77.865 | L3: 187.24743 | P3: 47.2348
A4: 2000.III | B4: =oilGDPnominal!C12 -> 4150331 | C4: =consumption_investment_governme!F12 -> 3164392 | D4: =consumption_investment_governme!H12 -> 947040 | E4: =oilGDPnominal!B12 -> 460321 | F4: 516011 | G4: =worldGDP!AU216 -> 0.501401 | H4: =oilGDPreal!B11 -> 1241308 | I4: 148436 | J4: 4906653 | K4: =US_GDP_deflator!B226 -> 78.309 | L4: 226.00242 | P4: 51.38669
A5: 2000.IV | B5: =oilGDPnominal!C13 -> 4400253 | C5: =consumption_investment_governme!F13 -> 3378859 | D5: =consumption_investment_governme!H13 -> 991669 | E5: =oilGDPnominal!B13 -> 462506 | F5: 631921 | G5: =worldGDP!AU217 -> 0.556709 | H5: =oilGDPreal!B12 -> 1241168 | I5: 34412 | J5: 5190343 | K5: =US_GDP_deflator!B227 -> 78.723 | L5: 217.7125 | P5: 53.38256
A6: 2001.I | B6: =oilGDPnominal!C14 -> 5130098 | C6: =consumption_investment_governme!F14 -> 4198533 | D6: =consumption_investment_governme!H14 -> 1053487 | E6: =oilGDPnominal!B14 -> 336056 | F6: 577101 | G6: =worldGDP!AU218 -> 0.283557 | H6: =oilGDPreal!B13 -> 1255388 | I6: -61201 | J6: 5904082 | K6: =US_GDP_deflator!B228 -> 79.204 | L6: 279.94644 | P6: 60.87082
A7: 2001.II | B7: =oilGDPnominal!C15 -> 5256978 | C7: =consumption_investment_governme!F15 -> 4375885 | D7: =consumption_investment_governme!H15 -> 1147563 | E7: =oilGDPnominal!B15 -> 327311 | F7: 582004 | G7: =worldGDP!AU219 -> 0.173391 | H7: =oilGDPreal!B14 -> 1232212 | I7: -267622 | J7: 6069620 | K7: =US_GDP_deflator!B229 -> 79.683 | L7: 261.42701 | P7: 61.91965
A8: 2001.III | B8: =oilGDPnominal!C16 -> 5336981 | C8: =consumption_investment_governme!F16 -> 4454342 | D8: =consumption_investment_governme!H16 -> 1212577 | E8: =oilGDPnominal!B16 -> 322417 | F8: 551198 | G8: =worldGDP!AU220 -> -0.042376 | H8: =oilGDPreal!B15 -> 1207624 | I8: -285424 | J8: 6159609 | K8: =US_GDP_deflator!B230 -> 80.004 | L8: 290.41246 | P8: 62.79239
A9: 2001.IV | B9: =oilGDPnominal!C17 -> 5535621 | C9: =consumption_investment_governme!F17 -> 4711126 | D9: =consumption_investment_governme!H17 -> 1247952 | E9: =oilGDPnominal!B17 -> 286737 | F9: 601693 | G9: =worldGDP!AU221 -> 0.167967 | H9: =oilGDPreal!B16 -> 1197778 | I9: -437784 | J9: 6335013 | K9: =US_GDP_deflator!B231 -> 80.268 | L9: 323.53177 | P9: 63.79604
A10: 2002.I | B10: =oilGDPnominal!C18 -> 5858861 | C10: =consumption_investment_governme!F18 -> 4935609 | D10: =consumption_investment_governme!H18 -> 1388559 | E10: =oilGDPnominal!B18 -> 340321 | F10: 622826 | G10: =worldGDP!AU222 -> 0.588085 | H10: =oilGDPreal!B17 -> 1196035 | I10: -420858 | J10: 6737551 | K10: =US_GDP_deflator!B232 -> 80.533 | L10: 337.2918 | P10: 66.94994
A11: 2002.II | B11: =oilGDPnominal!C19 -> 6100775 | C11: =consumption_investment_governme!F19 -> 5165450 | D11: =consumption_investment_governme!H19 -> 1460080 | E11: =oilGDPnominal!B19 -> 394787 | F11: 689584 | G11: =worldGDP!AU223 -> 0.773728 | H11: =oilGDPreal!B18 -> 1206414 | I11: -558124 | J11: 7086627 | K11: =US_GDP_deflator!B233 -> 80.821 | L11: 391.34819 | P11: 69.43713
A12: 2002.III | B12: =oilGDPnominal!C20 -> 6290885 | C12: =consumption_investment_governme!F20 -> 5297262 | D12: =consumption_investment_governme!H20 -> 1514534 | E12: =oilGDPnominal!B20 -> 416026 | F12: 721936 | G12: =worldGDP!AU224 -> 0.527771 | H12: =oilGDPreal!B19 -> 1189068 | I12: -482251 | J12: 7294132 | K12: =US_GDP_deflator!B234 -> 81.194 | L12: 313.86603 | P12: 70.99459
A13: 2002.IV | B13: =oilGDPnominal!C21 -> 6438429 | C13: =consumption_investment_governme!F21 -> 5401579 | D13: =consumption_investment_governme!H21 -> 1543432 | E13: =oilGDPnominal!B21 -> 399758 | F13: 772712 | G13: =worldGDP!AU225 -> 0.308766 | H13: =oilGDPreal!B20 -> 1153055 | I13: -363559 | J13: 7430635 | K13: =US_GDP_deflator!B235 -> 81.654 | L13: 333.90243 | P13: 72.10427
... A16: 2003.III | B16: =oilGDPnominal!C24 -> 7045127 | C16: =consumption_investment_governme!F24 -> 5866442 | D16: =consumption_investment_governme!H24 -> 1529914 | E16: =oilGDPnominal!B24 -> 509102 | F16: 889497 | G16: =worldGDP!AU228 -> 1.077838 | H16: =oilGDPreal!B23 -> 1265059 | I16: -125719 | J16: 8120465 | K16: =US_GDP_deflator!B238 -> 82.712 | L16: 420.11015 | P16: 77.60101
A17: 2003.IV | B17: =oilGDPnominal!C25 -> 7179216 | C17: =consumption_investment_governme!F25 -> 5903082 | D17: =consumption_investment_governme!H25 -> 1554456 | E17: =oilGDPnominal!B25 -> 587169 | F17: 913976 | G17: =worldGDP!AU229 -> 1.05367 | H17: =oilGDPreal!B24 -> 1483081 | I17: -141198 | J17: 8335886 | K17: =US_GDP_deflator!B239 -> 83.201 | L17: 358.65815 | P17: 77.06994 | R17: 45.062
A18: 2004.I | B18: =oilGDPnominal!C26 -> 7593729 | C18: =consumption_investment_governme!F26 -> 6306606 | D18: =consumption_investment_governme!H26 -> 1651726 | E18: =oilGDPnominal!B26 -> 704411 | F18: 989429 | G18: =worldGDP!AU230 -> 0.790881 | H18: =oilGDPreal!B25 -> 1643486 | I18: -186745 | J18: 8849273 | K18: =US_GDP_deflator!B240 -> 83.82 | L18: 351.81579 | P18: 79.78492
A19: 2004.II | B19: =oilGDPnominal!C27 -> 7702511 | C19: =consumption_investment_governme!F27 -> 6406699 | D19: =consumption_investment_governme!H27 -> 1772561 | E19: =oilGDPnominal!B27 -> 774451 | F19: 1001661 | G19: =worldGDP!AU231 -> 0.671886 | H19: =oilGDPreal!B26 -> 1746705 | I19: -172900 | J19: 9041596 | K19: =US_GDP_deflator!B241 -> 84.504 | L19: 421.47159 | P19: 80.13788
A20: 2004.III | B20: =oilGDPnominal!C28 -> 7754905 | C20: =consumption_investment_governme!F28 -> 6405966 | D20: =consumption_investment_governme!H28 -> 1836724 | E20: =oilGDPnominal!B28 -> 847667 | F20: 984387 | G20: =worldGDP!AU232 -> 0.591195 | H20: =oilGDPreal!B27 -> 1724686 | I20: -86264 | J20: 9207469 | K20: =US_GDP_deflator!B242 -> 85.056 | L20: 348.90898 | P20: 80.74398
A21: 2004.IV | B21: =oilGDPnominal!C29 -> 8010063 | C21: =consumption_investment_governme!F29 -> 6668037 | D21: =consumption_investment_governme!H29 -> 1948114 | E21: =oilGDPnominal!B29 -> 810428 | F21: 1007289 | G21: =worldGDP!AU233 -> 0.664294 | H21: =oilGDPreal!B28 -> 1750682 | I21: -123656 | J21: 9493323 | K21: =US_GDP_deflator!B243 -> 85.712 | L21: 359.99401 | P21: 81.63167 | R21: 38.665 | S21: =R21-R17 -> -6.397
A22: 2005.I | B22: =oilGDPnominal!C30 -> 8381666 | C22: =consumption_investment_governme!F30 -> 6872973 | D22: =consumption_investment_governme!H30 -> 1970809 | E22: =oilGDPnominal!B30 -> 948146 | F22: 1067573 | G22: =worldGDP!AU234 -> 0.78374 | H22: =oilGDPreal!B29 -> 1731598 | I22: -213444 | J22: 9858210 | K22: =US_GDP_deflator!B244 -> 86.391 | L22: 462.36779 | P22: 83.74419
A23: 2005.II | B23: =oilGDPnominal!C31 -> 8568497 | C23: =consumption_investment_governme!F31 -> 7047351 | D23: =consumption_investment_governme!H31 -> 2115210 | E23: =oilGDPnominal!B31 -> 1043477 | F23: 1094043 | G23: =worldGDP!AU235 -> 0.667814 | H23: =oilGDPreal!B30 -> 1736419 | I23: -177533 | J23: 10221018 | K23: =US_GDP_deflator!B245 -> 86.996 | L23: 415.07674 | P23: 85.62904
A24: 2005.III | B24: =oilGDPnominal!C32 -> 8787060 | C24: =consumption_investment_governme!F32 -> 7124759 | D24: =consumption_investment_governme!H32 -> 2163922 | E24: =oilGDPnominal!B32 -> 1230871 | F24: 1125814 | G24: =worldGDP!AU236 -> 0.935619 | H24: =oilGDPreal!B31 -> 1692897 | I24: 176053 | J24: 10645973 | K24: =US_GDP_deflator!B246 -> 87.783 | L24: 445.0674 | P24: 89.07334
A25: 2005.IV | B25: =oilGDPnominal!C33 -> 9087352 | C25: =consumption_investment_governme!F33 -> 7390813 | D25: =consumption_investment_governme!H33 -> 2226812 | E25: =oilGDPnominal!B33 -> 1158075 | F25: 1161235 | G25: =worldGDP!AU237 -> 0.795562 | H25: =oilGDPreal!B32 -> 1779305 | I25: -143482 | J25: 10781884 | K25: =US_GDP_deflator!B247 -> 88.489 | L25: 467.22117 | P25: 88.74567 | R25: 34.7 | S25: =R25-R21 -> -3.965
A26: 2006.I | B26: =oilGDPnominal!C34 -> 9391938 | C26: =consumption_investment_governme!F34 -> 7473628 | D26: =consumption_investment_governme!H34 -> 2289331 | E26: =oilGDPnominal!B34 -> 1377519 | F26: 1180967 | G26: =worldGDP!AU238 -> 1.052975 | H26: =oilGDPreal!B33 -> 1819765 | I26: 206457 | J26: 11312589 | K26: =US_GDP_deflator!B248 -> 89.107 | L26: 481.15361 | P26: 92.1362
A27: 2006.II | B27: =oilGDPnominal!C35 -> 9556770 | C27: =consumption_investment_governme!F35 -> 7640025 | D27: =consumption_investment_governme!H35 -> 2446002 | E27: =oilGDPnominal!B35 -> 1602913 | F27: 1213810 | G27: =worldGDP!AU239 -> 0.670682 | H27: =oilGDPreal!B34 -> 1859370 | I27: 98112 | J27: 11727184 | K27: =US_GDP_deflator!B249 -> 89.852 | L27: 504.67497 | P27: 94.21676
A28: 2006.III | B28: =oilGDPnominal!C36 -> 9768533 | C28: =consumption_investment_governme!F36 -> 7792795 | D28: =consumption_investment_governme!H36 -> 2546226 | E28: =oilGDPnominal!B36 -> 1587156 | F28: 1244480 | G28: =worldGDP!AU240 -> 0.345611 | H28: =oilGDPreal!B35 -> 1842611 | I28: 18302 | J28: 11941733 | K28: =US_GDP_deflator!B250 -> 90.481 | L28: 404.98089 | P28: 94.82836
A29: 2006.IV | B29: =oilGDPnominal!C37 -> 9960546 | C29: =consumption_investment_governme!F37 -> 7974442 | D29: =consumption_investment_governme!H37 -> 2478153 | E29: =oilGDPnominal!B37 -> 1251772 | F29: 1322646 | G29: =worldGDP!AU241 -> 0.981041 | H29: =oilGDPreal!B36 -> 1748041 | I29: 124728 | J29: 11820538 | K29: =US_GDP_deflator!B251 -> 90.815 | L29: 447.35482 | P29: 93.84005 | R29: 31.128 | S29: =R29-R25 -> -3.572
A30: 2007.I | B30: =oilGDPnominal!C38 -> 10109986 | C30: =consumption_investment_governme!F38 -> 8096780 | D30: =consumption_investment_governme!H38 -> 2580234 | E30: =oilGDPnominal!B38 -> 1262814 | F30: 1349454 | G30: =worldGDP!AU242 -> 0.721112 | H30: =oilGDPreal!B37 -> 1666169 | I30: -120496 | J30: 11972101 | K30: =US_GDP_deflator!B252 -> 91.708 | L30: 656.38665 | P30: 95.40522
A31: 2007.II | B31: =oilGDPnominal!C39 -> 10287446 | C31: =consumption_investment_governme!F39 -> 8215569 | D31: =consumption_investment_governme!H39 -> 2613022 | E31: =oilGDPnominal!B39 -> 1585173 | F31: 1402301 | G31: =worldGDP!AU243 -> 0.601542 | H31: =oilGDPreal!B38 -> 1655298 | I31: 102336 | J31: 12483035 | K31: =US_GDP_deflator!B253 -> 92.301 | L31: 813.8185 | P31: 98.74745
A32: 2007.III | B32: =oilGDPnominal!C40 -> 10507783 | C32: =consumption_investment_governme!F40 -> 8348009 | D32: =consumption_investment_governme!H40 -> 2631842 | E32: =oilGDPnominal!B40 -> 1746306 | F32: 1407775 | G32: =worldGDP!AU244 -> 0.457851 | H32: =oilGDPreal!B39 -> 1691341 | I32: 281581 | J32: 12923037 | K32: =US_GDP_deflator!B254 -> 92.776 | L32: 883.07294 | P32: 100.7919
A33: 2007.IV | B33: =oilGDPnominal!C41 -> 10854414 | C33: =consumption_investment_governme!F41 -> 8540920 | D33: =consumption_investment_governme!H41 -> 2768849 | E33: =oilGDPnominal!B41 -> 2156981 | F33: 1414679 | G33: =worldGDP!AU245 -> 0.740587 | H33: =oilGDPreal!B40 -> 1738466 | I33: 387641 | J33: 13629604 | K33: =US_GDP_deflator!B255 -> 93.145 | L33: 676.94979 | O33: =[1]quarterly!$B2 -> 39.765817 | P33: 104.8736 | Q33: 4.9983546 | R33: 28.464 | S33: =R33-R29 -> -2.664
A34: 2008.I | B34: =oilGDPnominal!C42 -> 11581175 | C34: =consumption_investment_governme!F42 -> 8948763 | D34: =consumption_investment_governme!H42 -> 2970329 | E34: =oilGDPnominal!B42 -> 2450552 | F34: 1670986 | G34: =worldGDP!AU246 -> 0.172714 | H34: =oilGDPreal!B41 -> 1728166 | I34: 801868 | J34: 14505871 | K34: =US_GDP_deflator!B256 -> 93.489 | L34: 1122.0941 | M34: 1362.2188 | N34: 937.04991 | O34: =[1]quarterly!$B3 -> . | P34: 109.8631
A35: 2008.II | B35: =oilGDPnominal!C43 -> 12230997 | C35: =consumption_investment_governme!F43 -> 9312999 | D35: =consumption_investment_governme!H43 -> 3344536 | E35: =oilGDPnominal!B43 -> 2981374 | F35: 1800173 | G35: =worldGDP!AU247 -> -0.039553 | H35: =oilGDPreal!B42 -> 1679075 | I35: 296710 | J35: 15788923 | K35: =US_GDP_deflator!B257 -> 93.99 | L35: 1468.3939 | M35: 1877.05 | N35: 1429.064 | O35: =[1]quarterly!$B4 -> 39.793649 | P35: 117.495 | Q35: 5.2227055
A36: 2008.III | B36: =oilGDPnominal!C44 -> 12941154 | C36: =consumption_investment_governme!F44 -> 9664597 | D36: =consumption_investment_governme!H44 -> 3703868 | E36: =oilGDPnominal!B44 -> 2859228 | F36: 1902052 | G36: =worldGDP!AU248 -> -0.545974 | H36: =oilGDPreal!B43 -> 1694710 | I36: -315809 | J36: 16213465 | K36: =US_GDP_deflator!B258 -> 94.69 | L36: 2020.4581 | M36: 2026.8234 | N36: 1702.842 | O36: =[1]quarterly!$B5 -> . | P36: 118.4395
A37: 2008.IV | B37: =oilGDPnominal!C45 -> 13024414 | C37: =consumption_investment_governme!F45 -> 10064904 | D37: =consumption_investment_governme!H45 -> 3799781 | E37: =oilGDPnominal!B45 -> 1482008 | F37: 1933577 | G37: =worldGDP!AU249 -> -1.923925 | H37: =oilGDPreal!B44 -> 1698965 | I37: -615805 | J37: 15254376 | K37: =US_GDP_deflator!B259 -> 94.986 | L37: 2246.4671 | M37: 1826.2011 | N37: 1464.3602 | O37: =[1]quarterly!$B6 -> 39.844144 | P37: 109.589 | Q37: 5.951463 | R37: 24.229 | S37: =R37-R33 -> -4.235
A38: 2009.I | B38: =oilGDPnominal!C46 -> 13042531 | C38: =consumption_investment_governme!F46 -> 9799156 | D38: =consumption_investment_governme!H46 -> 3638386 | E38: =oilGDPnominal!B46 -> 1054725 | F38: 2020721 | G38: =worldGDP!AU250 -> -2.252955 | H38: =oilGDPreal!B45 -> 1764343 | I38: -563681 | J38: 15022003 | K38: =US_GDP_deflator!B260 -> 94.976 | L38: 1481.7728 | M38: 1383.2106 | N38: 975.54097 | O38: =[1]quarterly!$B7 -> . | P38: 109.4803
A39: 2009.II | B39: =oilGDPnominal!C47 -> 13139527 | C39: =consumption_investment_governme!F47 -> 9634405 | D39: =consumption_investment_governme!H47 -> 3538406 | E39: =oilGDPnominal!B47 -> 1525729 | F39: 2100079 | G39: =worldGDP!AU251 -> 0.155632 | H39: =oilGDPreal!B46 -> 1801773 | I39: -224241 | J39: 15588869 | K39: =US_GDP_deflator!B261 -> 94.838 | L39: 1510.2219 | M39: 1294.8698 | N39: 851.76278 | O39: =[1]quarterly!$B8 -> . | P39: 114.0894
A40: 2009.III | B40: =oilGDPnominal!C48 -> 13352010 | C40: =consumption_investment_governme!F48 -> 9658411 | D40: =consumption_investment_governme!H48 -> 3493945 | E40: =oilGDPnominal!B48 -> 1617564 | F40: 2189216 | G40: =worldGDP!AU252 -> 0.55993 | H40: =oilGDPreal!B47 -> 1667167 | I40: -212924 | J40: 15779977 | K40: =US_GDP_deflator!B262 -> 94.938 | L40: 1568.8861 | M40: 1231.5664 | N40: 804.53628 | O40: =[1]quarterly!$B9 -> . | P40: 116.2044
A41: 2009.IV | B41: =oilGDPnominal!C49 -> 13584681 | C41: =consumption_investment_governme!F49 -> 9821313 | D41: =consumption_investment_governme!H49 -> 3586952 | E41: =oilGDPnominal!B49 -> 1696508 | F41: 2271259 | G41: =worldGDP!AU253 -> 0.940041 | H41: =oilGDPreal!B48 -> 1596198 | I41: -3616 | J41: 16128837 | K41: =US_GDP_deflator!B263 -> 95.259 | L41: 1712.3944 | M41: 1814.6155 | N41: 1222.1189 | O41: =[1]quarterly!$B10 -> 38.949399 | P41: 118.6528 | Q41: 6.47131 | R41: 18.568 | S41: =R41-R37 -> -5.661
A42: 2010.I | B42: =oilGDPnominal!C50 -> 14076102 | C42: =consumption_investment_governme!F50 -> 10500363 | D42: =consumption_investment_governme!H50 -> 3975994 | E42: =oilGDPnominal!B50 -> 1998698 | F42: 2234239 | G42: =worldGDP!AU254 -> 0.619244 | H42: =oilGDPreal!B49 -> 1582738 | I42: -631341 | J42: 16762628 | K42: =US_GDP_deflator!B264 -> 95.499 | L42: 1286.8867 | M42: 2028.207 | N42: 1445.9398 | O42: =[1]quarterly!$B11 -> . | P42: 122.0892
...

Sheet monthly
B1: Foreign_interest_rate | C1: Oil_price | D1: EMBI | E1: Government_consumption | F1: Government_wages | G1: Government_FBKF | H1: Government_transfers | I1: Consumption_taxreceipts | J1: Income_taxreceipts | K1: Laborincome_taxreceipts | L1: Capitalincome_taxreceipts | M1: Private_externaldebt | N1: Public_externaldebt | O1: Public_internaldebt | P1: rer | Q1: oil_production
A2: 36526 | B2: 5.499 | C2: =oilprice!B2 -> 22.84 | D2: =EMBI!B2 -> 3672.8 | E2: =g_consumption!B2 -> 28.343359 | F2: =g_wages!B2 -> 5.0834107 | G2: =g_fbkf!B2 -> 28.949103 | H2: =g_transfers!B2 -> 30.260721 | I2: =tax_receipts!C2 -> 56.500429 | J2: =tax_receipts!F2 -> 12.971592 | K2: =J2*tax_receipts!G2/(tax_receipts!G2+tax_receipts!H2) -> 0.50686816 | L2: =J2-K2 -> 12.464724 | M2: =debt!B2 -> 2568.8 | N2: =debt!C2 -> 13646.8 | O2: =debt!D2 -> 3303.4 | P2: =real_exchange_rate!B2 -> 214.06015
A3: 36557 | B3: 5.727 | C3: =oilprice!B3 -> 24.26 | D3: =EMBI!B3 -> 4043.05 | E3: =g_consumption!B3 -> 22.008969 | F3: =g_wages!B3 -> 76.140046 | G3: =g_fbkf!B3 -> 33.752032 | H3: =g_transfers!B3 -> 68.043456 | I3: =tax_receipts!C3 -> 53.671587 | J3: =tax_receipts!F3 -> 13.401321 | K3: =J3*tax_receipts!G3/(tax_receipts!G3+tax_receipts!H3) -> 7.2685158 | L3: =J3-K3 -> 6.132805 | M3: =debt!B3 -> 2532.9 | N3: =debt!C3 -> 13699.5 | O3: =debt!D3 -> 3289.7 | P3: =real_exchange_rate!B3 -> 196.54991
A4: 36586 | B4: 5.863913 | C4: =oilprice!B4 -> 24.88 | D4: =EMBI!B4 -> 3115.2174 | E4: =g_consumption!B4 -> 26.232688 | F4: =g_wages!B4 -> 47.612526 | G4: =g_fbkf!B4 -> 44.729746 | H4: =g_transfers!B4 -> 53.702372 | I4: =tax_receipts!C4 -> 53.359876 | J4: =tax_receipts!F4 -> 18.682313 | K4: =J4*tax_receipts!G4/(tax_receipts!G4+tax_receipts!H4) -> 2.5440414 | L4: =J4-K4 -> 16.138272 | M4: =debt!B4 -> 2440.5 | N4: =debt!C4 -> 13770 | O4: =debt!D4 -> 3295.3 | P4: =real_exchange_rate!B4 -> 183.59854
A5: 36617 | B5: 5.8215789 | C5: =oilprice!B5 -> 21.79 | D5: =EMBI!B5 -> 3372.0526 | E5: =g_consumption!B5 -> 20.681453 | F5: =g_wages!B5 -> 45.337874 | G5: =g_fbkf!B5 -> 70.471063 | H5: =g_transfers!B5 -> 72.701219 | I5: =tax_receipts!C5 -> 61.710057 | J5: =tax_receipts!F5 -> 49.929 | K5: =J5*tax_receipts!G5/(tax_receipts!G5+tax_receipts!H5) -> 6.9671429 | L5: =J5-K5 -> 42.961857 | M5: =debt!B5 -> 2381.4 | N5: =debt!C5 -> 13969.4 | O5: =debt!D5 -> 3256.9 | P5: =real_exchange_rate!B5 -> 166.29552
A6: 36647 | B6: 5.9945455 | C6: =oilprice!B6 -> 24.35 | D6: =EMBI!B6 -> 3971.7273 | E6: =g_consumption!B6 -> 28.204444 | F6: =g_wages!B6 -> 47.78272 | G6: =g_fbkf!B6 -> 58.448924 | H6: =g_transfers!B6 -> 47.719765 | I6: =tax_receipts!C6 -> 59.4237 | J6: =tax_receipts!F6 -> 19.404 | K6: =J6*tax_receipts!G6/(tax_receipts!G6+tax_receipts!H6) -> 6.9855073 | L6: =J6-K6 -> 12.418493 | M6: =debt!B6 -> 2409.7 | N6: =debt!C6 -> 14011.6 | O6: =debt!D6 -> 3230.9 | P6: =real_exchange_rate!B6 -> 155.41638
A7: 36678 | B7: 5.8618182 | C7: =oilprice!B7 -> 26.59 | D7: =EMBI!B7 -> 4416.2273 | E7: =g_consumption!B7 -> 34.471106 | F7: =g_wages!B7 -> 57.056738 | G7: =g_fbkf!B7 -> 67.945128 | H7: =g_transfers!B7 -> 65.212784 | I7: =tax_receipts!C7 -> 80.155 | J7: =tax_receipts!F7 -> 21.167 | K7: =J7*tax_receipts!G7/(tax_receipts!G7+tax_receipts!H7) -> 5.2425262 | L7: =J7-K7 -> 15.924474 | M7: =debt!B7 -> 2389 | N7: =debt!C7 -> 14073.5 | O7: =debt!D7 -> 3219.9 | P7: =real_exchange_rate!B7 -> 149.30333
A8: 36708 | B8: 6.1425 | C8: =oilprice!B8 -> 24.19 | D8: =EMBI!B8 -> 3795.75 | E8: =g_consumption!B8 -> 34.365728 | F8: =g_wages!B8 -> 62.032085 | G8: =g_fbkf!B8 -> 67.404171 | H8: =g_transfers!B8 -> 54.83377 | I8: =tax_receipts!C8 -> 75.1381 | J8: =tax_receipts!F8 -> 28.1404 | K8: =J8*tax_receipts!G8/(tax_receipts!G8+tax_receipts!H8) -> 3.7716353 | L8: =J8-K8 -> 24.368765 | M8: =debt!B8 -> 2437.3 | N8: =debt!C8 -> 13914.5 | O8: =debt!D8 -> 3207.1 | P8: =real_exchange_rate!B8 -> 145.46973
A9: 36739 | B9: 6.2773913 | C9: =oilprice!B9 -> 25.74 | D9: =EMBI!B9 -> 2574.6957 | E9: =g_consumption!B9 -> 34.603116 | F9: =g_wages!B9 -> 70.840883 | G9: =g_fbkf!B9 -> 73.141681 | H9: =g_transfers!B9 -> 87.676633 | I9: =tax_receipts!C9 -> 86.7894 | J9: =tax_receipts!F9 -> 22.751 | K9: =J9*tax_receipts!G9/(tax_receipts!G9+tax_receipts!H9) -> 8.314871 | L9: =J9-K9 -> 14.436129 | M9: =debt!B9 -> 2286.3 | N9: =debt!C9 -> 11226.3 | O9: =debt!D9 -> 3203.3 | P9: =real_exchange_rate!B9 -> 142.25779
A10: 36770 | B10: 6.175 | C10: =oilprice!B10 -> 27.96 | D10: =EMBI!B10 -> 1297.05 | E10: =g_consumption!B10 -> 34.606416 | F10: =g_wages!B10 -> 63.421064 | G10: =g_fbkf!B10 -> 86.696516 | H10: =g_transfers!B10 -> 48.793556 | I10: =tax_receipts!C10 -> 89.129 | J10: =tax_receipts!F10 -> 28.82 | K10: =J10*tax_receipts!G10/(tax_receipts!G10+tax_receipts!H10) -> 5.6641624 | L10: =J10-K10 -> 23.155838 | M10: =debt!B10 -> 2331.7 | N10: =debt!C10 -> 11257.8 | O10: =debt!D10 -> 3164.8 | P10: =real_exchange_rate!B10 -> 136.55919
A11: 36800 | B11: 6.2947619 | C11: =oilprice!B11 -> 27.91 | D11: =EMBI!B11 -> 1300.6667 | E11: =g_consumption!B11 -> 48.39668 | F11: =g_wages!B11 -> 68.159542 | G11: =g_fbkf!B11 -> 89.389387 | H11: =g_transfers!B11 -> 71.999165 | I11: =tax_receipts!C11 -> 89.424 | J11: =tax_receipts!F11 -> 25.128 | K11: =J11*tax_receipts!G11/(tax_receipts!G11+tax_receipts!H11) -> 9.2846337 | L11: =J11-K11 -> 15.843366 | M11: =debt!B11 -> 2318.4 | N11: =debt!C11 -> 11186.1 | O11: =debt!D11 -> 3129.3 | P11: =real_exchange_rate!B11 -> 132.41475
A12: 36831 | B12: 6.3561905 | C12: =oilprice!B12 -> 27.27 | D12: =EMBI!B12 -> 1352.5238 | E12: =g_consumption!B12 -> 44.926558 | F12: =g_wages!B12 -> 93.931982 | G12: =g_fbkf!B12 -> 66.72828 | H12: =g_transfers!B12 -> 69.518518 | I12: =tax_receipts!C12 -> 98.509 | J12: =tax_receipts!F12 -> 25.063 | K12: =J12*tax_receipts!G12/(tax_receipts!G12+tax_receipts!H12) -> 13.56032 | L12: =J12-K12 -> 11.50268 | M12: =debt!B12 -> 2292.7 | N12: =debt!C12 -> 11161.9 | O12: =debt!D12 -> 3113.9 | P12: =real_exchange_rate!B12 -> 129.92809
A13: 36861 | B13: 5.937 | C13: =oilprice!B13 -> 20.58 | D13: =EMBI!B13 -> 1451.1 | E13: =g_consumption!B13 -> 53.045543 | F13: =g_wages!B13 -> 123.59982 | G13: =g_fbkf!B13 -> 94.582664 | H13: =g_transfers!B13 -> 209.58083 | I13: =tax_receipts!C13 -> 106.589 | J13: =tax_receipts!F13 -> 28.029 | K13: =J13*tax_receipts!G13/(tax_receipts!G13+tax_receipts!H13) -> 7.2290678 | L13: =J13-K13 -> 20.799932 | M13: =debt!B13 -> 2229.1 | N13: =debt!C13 -> 11335.4 | O13: =debt!D13 -> 2833.5 | P13: =real_exchange_rate!B13 -> 127.33782
... A49: 37956 | B49: 0.91454545 | C49: =oilprice!B49 -> 26.1 | D49: =EMBI!B49 -> 840.36364 | E49: =g_consumption!B49 -> 81.542 | F49: =g_wages!B49 -> 303.51 | G49: =g_fbkf!B49 -> 142.4708 | H49: =g_transfers!B49 -> 113.23333 | I49: =tax_receipts!C49 -> 155.26783 | J49: =tax_receipts!F49 -> 35.373268 | K49: =J49*tax_receipts!G49/(tax_receipts!G49+tax_receipts!H49) -> 8.0676312 | L49: =J49-K49 -> 27.305637 | M49: =debt!B49 -> 5101.9 | N49: =debt!C49 -> 11493.2 | O49: =debt!D49 -> 3016.2 | P49: =real_exchange_rate!B49 -> 97.601484
A50: 37987 | B50: 0.9005 | C50: =oilprice!B50 -> 26.91 | D50: =EMBI!B50 -> 724.36842 | E50: =g_consumption!B50 -> 68.809364 | F50: =g_wages!B50 -> 183.50193 | G50: =g_fbkf!B50 -> 44.500286 | H50: =g_transfers!B50 -> 90.885417 | I50: =tax_receipts!C50 -> 177.39053 | J50: =tax_receipts!F50 -> 61.678288 | K50: =J50*tax_receipts!G50/(tax_receipts!G50+tax_receipts!H50) -> 29.214398 | L50: =J50-K50 -> 32.46389 | M50: =debt!B50 -> 5534.3 | N50: =debt!C50 -> 11471.1 | O50: =debt!D50 -> 2965.9 | P50: =real_exchange_rate!B50 -> 98.886259 | Q50: 15728.453
A51: 38018 | B51: 0.94473684 | C51: =oilprice!B51 -> 26.91 | D51: =EMBI!B51 -> 746 | E51: =g_consumption!B51 -> 75.029731 | F51: =g_wages!B51 -> 214.6163 | G51: =g_fbkf!B51 -> 100.87669 | H51: =g_transfers!B51 -> 96.719843 | I51: =tax_receipts!C51 -> 129.74246 | J51: =tax_receipts!F51 -> 32.63717 | K51: =J51*tax_receipts!G51/(tax_receipts!G51+tax_receipts!H51) -> 19.812754 | L51: =J51-K51 -> 12.824416 | M51: =debt!B51 -> 5461.4 | N51: =debt!C51 -> 11393.2 | O51: =debt!D51 -> 3056.6 | P51: =real_exchange_rate!B51 -> 98.192066 | Q51: 15163.05
A52: 38047 | B52: 0.95347826 | C52: =oilprice!B52 -> 26.28 | D52: =EMBI!B52 -> 723.59091 | E52: =g_consumption!B52 -> 73.662607 | F52: =g_wages!B52 -> 218.068 | G52: =g_fbkf!B52 -> 150.0344 | H52: =g_transfers!B52 -> 98.224714 | I52: =tax_receipts!C52 -> 158.58708 | J52: =tax_receipts!F52 -> 49.567963 | K52: =J52*tax_receipts!G52/(tax_receipts!G52+tax_receipts!H52) -> 41.576216 | L52: =J52-K52 -> 7.9917475 | M52: =debt!B52 -> 5656.4 | N52: =debt!C52 -> 11369.6 | O52: =debt!D52 -> 3159.7 | P52: =real_exchange_rate!B52 -> 97.342456 | Q52: 15210.939
A53: 38078 | B53: 0.95809524 | C53: =oilprice!B53 -> 26.96 | D53: =EMBI!B53 -> 762.95238 | E53: =g_consumption!B53 -> 82.760617 | F53: =g_wages!B53 -> 209.56601 | G53: =g_fbkf!B53 -> 134.70646 | H53: =g_transfers!B53 -> 122.58889 | I53: =tax_receipts!C53 -> 158.899 | J53: =tax_receipts!F53 -> 176.16476 | K53: =J53*tax_receipts!G53/(tax_receipts!G53+tax_receipts!H53) -> 1.5709461 | L53: =J53-K53 -> 174.59382 | M53: =debt!B53 -> 5612 | N53: =debt!C53 -> 11218.3 | O53: =debt!D53 -> 3230.1 | P53: =real_exchange_rate!B53 -> 96.762235 | Q53: 15992.684
A54: 38108 | B54: 1.0395 | C54: =oilprice!B54 -> 31.19 | D54: =EMBI!B54 -> 920.5 | E54: =g_consumption!B54 -> 83.440752 | F54: =g_wages!B54 -> 218.31842 | G54: =g_fbkf!B54 -> 146.649 | H54: =g_transfers!B54 -> 109.39675 | I54: =tax_receipts!C54 -> 157.1788 | J54: =tax_receipts!F54 -> 40.013235 | K54: =J54*tax_receipts!G54/(tax_receipts!G54+tax_receipts!H54) -> 10.863038 | L54: =J54-K54 -> 29.150197 | M54: =debt!B54 -> 5013.3 | N54: =debt!C54 -> 11236.3 | O54: =debt!D54 -> 3249.6 | P54: =real_exchange_rate!B54 -> 96.472125 | Q54: 16404.33
A55: 38139 | B55: 1.2880952 | C55: =oilprice!B55 -> 29.86 | D55: =EMBI!B55 -> 886.09091 | E55: =g_consumption!B55 -> 86.025 | F55: =g_wages!B55 -> 197.38619 | G55: =g_fbkf!B55 -> 141.81351 | H55: =g_transfers!B55 -> 125.55174 | I55: =tax_receipts!C55 -> 157.17638 | J55: =tax_receipts!F55 -> 35.306512 | K55: =J55*tax_receipts!G55/(tax_receipts!G55+tax_receipts!H55) -> 13.622886 | L55: =J55-K55 -> 21.683625 | M55: =debt!B55 -> 5389.5 | N55: =debt!C55 -> 11165.1 | O55: =debt!D55 -> 3270.9 | P55: =real_exchange_rate!B55 -> 97.601484 | Q55: 16127.136
A56: 38169 | B56: 1.357619 | C56: =oilprice!B56 -> 31.29 | D56: =EMBI!B56 -> 921.61905 | E56: =g_consumption!B56 -> 88.357 | F56: =g_wages!B56 -> 217.9766 | G56: =g_fbkf!B56 -> 109.84181 | H56: =g_transfers!B56 -> 112.18547 | I56: =tax_receipts!C56 -> 158.66888 | J56: =tax_receipts!F56 -> 77.432545 | K56: =J56*tax_receipts!G56/(tax_receipts!G56+tax_receipts!H56) -> 25.655206 | L56: =J56-K56 -> 51.777339 | M56: =debt!B56 -> 5318.7 | N56: =debt!C56 -> 11090.7 | O56: =debt!D56 -> 3325.4 | P56: =real_exchange_rate!B56 -> 98.782648 | Q56: 16451.144
A57: 38200 | B57: 1.5031818 | C57: =oilprice!B57 -> 34.05 | D57: =EMBI!B57 -> 836.13636 | E57: =g_consumption!B57 -> 91.747 | F57: =g_wages!B57 -> 210.3767 | G57: =g_fbkf!B57 -> 113.16003 | H57: =g_transfers!B57 -> 134.88116 | I57: =tax_receipts!C57 -> 162.06584 | J57: =tax_receipts!F57 -> 39.392742 | K57: =J57*tax_receipts!G57/(tax_receipts!G57+tax_receipts!H57) -> 12.894474 | L57: =J57-K57 -> 26.498268 | M57: =debt!B57 -> 5432.9 | N57: =debt!C57 -> 11028.4 | O57: =debt!D57 -> 3480.1 | P57: =real_exchange_rate!B57 -> 98.927704 | Q57: 16474.526
A58: 38231 | B58: 1.6814286 | C58: =oilprice!B58 -> 32.52 | D58: =EMBI!B58 -> 801.7619 | E58: =g_consumption!B58 -> 87.895 | F58: =g_wages!B58 -> 219.099 | G58: =g_fbkf!B58 -> 118.36218 | H58: =g_transfers!B58 -> 138.8587 | I58: =tax_receipts!C58 -> 146.16421 | J58: =tax_receipts!F58 -> 71.718163 | K58: =J58*tax_receipts!G58/(tax_receipts!G58+tax_receipts!H58) -> 19.673466 | L58: =J58-K58 -> 52.044697 | M58: =debt!B58 -> 5804 | N58: =debt!C58 -> 11072 | O58: =debt!D58 -> 3491.2 | P58: =real_exchange_rate!B58 -> 99.37323 | Q58: 15662.468
A59: 38261 | B59: 1.7945 | C59: =oilprice!B59 -> 37.18 | D59: =EMBI!B59 -> 731.05 | E59: =g_consumption!B59 -> 80.73 | F59: =g_wages!B59 -> 200.539 | G59: =g_fbkf!B59 -> 137.47891 | H59: =g_transfers!B59 -> 118.06564 | I59: =tax_receipts!C59 -> 170.9505 | J59: =tax_receipts!F59 -> 39.143948 | K59: =J59*tax_receipts!G59/(tax_receipts!G59+tax_receipts!H59) -> 3.794402 | L59: =J59-K59 -> 35.349546 | M59: =debt!B59 -> 5849.1 | N59: =debt!C59 -> 11045.3 | O59: =debt!D59 -> 3624.2 | P59: =real_exchange_rate!B59 -> 100.12959 | Q59: 16401.195
A60: 38292 | B60: 2.1075 | C60: =oilprice!B60 -> 30.58 | D60: =EMBI!B60 -> 721.95 | E60: =g_consumption!B60 -> 76.503 | F60: =g_wages!B60 -> 204.63044 | G60: =g_fbkf!B60 -> 103.92969 | H60: =g_transfers!B60 -> 138.01434 | I60: =tax_receipts!C60 -> 170.22556 | J60: =tax_receipts!F60 -> 40.903657 | K60: =J60*tax_receipts!G60/(tax_receipts!G60+tax_receipts!H60) -> 7.0681122 | L60: =J60-K60 -> 33.835544 | M60: =debt!B60 -> 6157.4 | N60: =debt!C60 -> 11051.8 | O60: =debt!D60 -> 3570.1 | P60: =real_exchange_rate!B60 -> 101.50762 | Q60: 16010.756
A61: 38322 | B61: 2.2227273 | C61: =oilprice!B61 -> 25.67 | D61: =EMBI!B61 -> 710.59091 | E61: =g_consumption!B61 -> 138.29711 | F61: =g_wages!B61 -> 291.943 | G61: =g_fbkf!B61 -> 191.56598 | H61: =g_transfers!B61 -> 184.11227 | I61: =tax_receipts!C61 -> 174.69513 | J61: =tax_receipts!F61 -> 37.97234 | K61: =J61*tax_receipts!G61/(tax_receipts!G61+tax_receipts!H61) -> 21.195 | L61: =J61-K61 -> 16.77734 | M61: =debt!B61 -> 5948.5 | N61: =debt!C61 -> 11061.6 | O61: =debt!D61 -> 3489.1 | P61: =real_exchange_rate!B61 -> 103.09286 | Q61: 16688.453
... A241: 43800 | B241: 1.5652381 | C241: =oilprice!B241 -> 54.026274 | D241: =EMBI!B241 -> 937.87097 | E241: =g_consumption!B241 -> 0 | F241: =g_wages!B241 -> 0 | G241: =g_fbkf!B241 -> 0 | H241: =g_transfers!B241 -> 0 | I241: =tax_receipts!C241 -> 560.59832 | J241: =tax_receipts!F241 -> 252.67936 | K241: =J241*tax_receipts!G241/(tax_receipts!G241+tax_receipts!H241) -> 117.6798 | L241: =J241-K241 -> 134.99956 | M241: =debt!B241 -> 11174.868 | N241: =debt!C241 -> 41495.584 | O241: =debt!D241 -> 15843.636 | P241: =real_exchange_rate!B241 -> 102.66404 | Q241: 16800.809

Sheet annual
B1: I_g | C1: I_p | D1: I_total | E1: Government_debt
A2: 2000 | B2: 957 | C2: 2526 | D2: 3483
A3: 2001 | B3: 1524 | C3: 3138 | D3: 4662
A4: 2002 | B4: 1812 | C4: 4095 | D4: 5907
A5: 2003 | B5: 1824 | C5: 4416 | D5: 6240 | E5: 45.062
A6: 2004 | B6: 1941 | C6: 5268 | D6: 7209 | E6: 38.665
A7: 2005 | B7: 1943 | C7: 6533 | D7: 8476 | E7: 34.7
A8: 2006 | B8: 1982 | C8: 7777 | D8: 9759 | E8: 31.128
A9: 2007 | B9: 3337 | C9: 7257 | D9: 10594 | E9: 28.464
A10: 2008 | B10: 4454 | C10: 9365 | D10: 13819 | E10: 24.229
A11: 2009 | B11: 6794 | C11: 7464 | D11: 14258 | E11: 18.568
A12: 2010 | B12: 7576 | C12: 9551 | D12: 17127 | E12: 17.696
A13: 2011 | B13: 8744 | C13: 11727 | D13: 20471 | E13: 16.789
A14: 2012 | B14: 11065.548 | C14: 12642.29 | D14: 23707.838 | E14: 17.496
A15: 2013 | B15: 15155 | C15: 11057 | D15: 26212 | E15: 20.031
A16: 2014 | B16: 15953 | C16: 11731 | D16: 27684 | E16: 27.973
A17: 2015 | B17: 13344 | C17: 13046 | D17: 26390 | E17: 35.218
A18: 2016 sd | B18: 11463.735 | C18: 13617.053 | D18: 25080.788 | E18: 44.582
A19: 2017 p | B19: 11096.674 | C19: 15399.582 | D19: 26496.256 | E19: 47.03
A20: 2018 p | B20: 8619.493 | C20: 18898.191 | D20: 27517.684 | E20: 49.087
A21: 2019 p | B21: 8468 | C21: 18439.554 | D21: 26908 | E21: 51.411

Sheet real_exchange_rate
B1: rer
A2: 36526 | B2: 214.06015
A3: 36557 | B3: 196.54991
A4: 36586 | B4: 183.59854
A5: 36617 | B5: 166.29552
A6: 36647 | B6: 155.41638
A7: 36678 | B7: 149.30333
A8: 36708 | B8: 145.46973
A9: 36739 | B9: 142.25779
A10: 36770 | B10: 136.55919
A11: 36800 | B11: 132.41475
A12: 36831 | B12: 129.92809
A13: 36861 | B13: 127.33782
... A241: 43800 | B241: 102.66404

Sheet debt
B1: Private_externaldebt | C1: Public_externaldebt | D1: Public_internaldebt
A2: 36526 | B2: 2568.8 | C2: 13646.8 | D2: 3303.4
A3: 36557 | B3: 2532.9 | C3: 13699.5 | D3: 3289.7
A4: 36586 | B4: 2440.5 | C4: 13770 | D4: 3295.3
A5: 36617 | B5: 2381.4 | C5: 13969.4 | D5: 3256.9
A6: 36647 | B6: 2409.7 | C6: 14011.6 | D6: 3230.9
A7: 36678 | B7: 2389 | C7: 14073.5 | D7: 3219.9
A8: 36708 | B8: 2437.3 | C8: 13914.5 | D8: 3207.1
A9: 36739 | B9: 2286.3 | C9: 11226.3 | D9: 3203.3
A10: 36770 | B10: 2331.7 | C10: 11257.8 | D10: 3164.8
A11: 36800 | B11: 2318.4 | C11: 11186.1 | D11: 3129.3
A12: 36831 | B12: 2292.7 | C12: 11161.9 | D12: 3113.9
A13: 36861 | B13: 2229.1 | C13: 11335.4 | D13: 2833.5
... A241: 43800 | B241: 11174.868 | C241: 41495.584 | D241: 15843.636

Sheet consumption_investment_governme
A1: Menú Principal
A4: OFERTA Y UTILIZACIÓN FINAL DE BIENES Y SERVICIOS
A5: Miles de US dólares
A7: Variables | B7: P.I.B. | C7: Importaciones de bienes y servicios (fob) | D7: Oferta final | E7: Demanda interna | F7: Gasto de Consumo final Hogares (*) | G7: Gasto de Consumo final Gobierno General | H7: FBKF | I7: Variación de existencias | J7: Exportaciones de bienes y servicios (fob) | K7: Utilización final | M7: trade balance
A8: Trimestres
A10: 2000.I | B10: 3819126 | C10: 1120302 | D10: 4939428 | E10: 3433046 | F10: 2445053 | G10: 175154 | H10: 723232 | I10: 89607 | J10: 1506382 | K10: 4939428 | M10: =J10-C10 -> 386080
A11: 2000.II | B11: 4402479 | C11: 1165977 | D11: 5568456 | E11: 4093878 | F11: 2841942 | G11: 389776 | H11: 821301 | I11: 40859 | J11: 1474578 | K11: 5568456 | M11: =J11-C11 -> 308601
A12: 2000.III | B12: 4906653 | C12: 1344968 | D12: 6251621 | E12: 4758217 | F12: 3164392 | G12: 516011 | H12: 947040 | I12: 130774 | J12: 1493404 | K12: 6251621 | M12: =J12-C12 -> 148436
A13: 2000.IV | B13: 5190343 | C13: 1376539 | D13: 6566882 | E13: 5155931 | F13: 3378859 | G13: 631921 | H13: 991669 | I13: 153482 | J13: 1410951 | K13: 6566882 | M13: =J13-C13 -> 34412
A14: 2001.I | B14: 5904082 | C14: 1558735 | D14: 7462817 | E14: 5965283 | F14: 4198533 | G14: 577101 | H14: 1053487 | I14: 136162 | J14: 1497534 | K14: 7462817 | M14: =J14-C14 -> -61201
A15: 2001.II | B15: 6069620 | C15: 1656183 | D15: 7725803 | E15: 6337242 | F15: 4375885 | G15: 582004 | H15: 1147563 | I15: 231790 | J15: 1388561 | K15: 7725803 | M15: =J15-C15 -> -267622
A16: 2001.III | B16: 6159609 | C16: 1693120 | D16: 7852729 | E16: 6445033 | F16: 4454342 | G16: 551198 | H16: 1212577 | I16: 226916 | J16: 1407696 | K16: 7852729 | M16: =J16-C16 -> -285424
A17: 2001.IV | B17: 6335013 | C17: 1826210 | D17: 8161223 | E17: 6772797 | F17: 4711126 | G17: 601693 | H17: 1247952 | I17: 212026 | J17: 1388426 | K17: 8161223 | M17: =J17-C17 -> -437784
A18: 2002.I | B18: 6737551 | C18: 1840720 | D18: 8578271 | E18: 7158409 | F18: 4935609 | G18: 622826 | H18: 1388559 | I18: 211415 | J18: 1419862 | K18: 8578271 | M18: =J18-C18 -> -420858
A19: 2002.II | B19: 7086627 | C19: 2073234 | D19: 9159861 | E19: 7644751 | F19: 5165450 | G19: 689584 | H19: 1460080 | I19: 329637 | J19: 1515110 | K19: 9159861 | M19: =J19-C19 -> -558124
A20: 2002.III | B20: 7294132 | C20: 2054515 | D20: 9348647 | E20: 7776383 | F20: 5297262 | G20: 721936 | H20: 1514534 | I20: 242651 | J20: 1572264 | K20: 9348647 | M20: =J20-C20 -> -482251
A21: 2002.IV | B21: 7430635 | C21: 1992169 | D21: 9422804 | E21: 7794194 | F21: 5401579 | G21: 772712 | H21: 1543432 | I21: 76471 | J21: 1628610 | K21: 9422804 | M21: =J21-C21 -> -363559
... A89: 2019.IV | B89: 26817695 | C89: 6039016 | D89: 32856711 | E89: 26502918 | F89: 16252564 | G89: 3893234 | H89: 6644595 | I89: -287475 | J89: 6353793 | K89: 32856711 | M89: =J89-C89 -> 314777
A90: 2020.I | B90: 25878598 | C90: 5721667 | D90: 31600265 | E90: 25431100 | F90: 15861715 | G90: 3655204 | H90: 6223560 | I90: -309379 | J90: 6169165 | K90: 31600265
A92: (*) incluye el gasto de consumo de las Instituciones sin fines de lucro al servicio de los hogares, ISFLSH
A93: Elaboración: BANCO CENTRAL DEL ECUADOR

Sheet oilGDPreal
A1: Menú Principal
A3: VALOR AGREGADO BRUTO PETROLERO (*) Y NO PETROLERO
B5: Miles de US dólares, 2007=100 | F5: Tasas de variación t/t-1 | J5: Tasas de variación t/t-4
A6: Industrias | B6: VALOR AGREGADO PETROLERO | C6: VALOR AGREGADO NO PETROLERO | D6: OTROS ELEMENTOS DEL PIB (**) | E6: P.I.B. | F6: VALOR AGREGADO PETROLERO | G6: VALOR AGREGADO NO PETROLERO | H6: OTROS ELEMENTOS DEL PIB (**) | I6: P.I.B. | J6: VALOR AGREGADO PETROLERO | K6: VALOR AGREGADO NO PETROLERO | L6: OTROS ELEMENTOS DEL PIB | M6: P.I.B.
A7: Trimestres
A9: 2000.I | B9: 1218387 | C9: 7505878 | D9: 410322 | E9: 9134587
A10: 2000.II | B10: 1191946 | C10: 7713590 | D10: 414878 | E10: 9320414 | F10: -2.1701643 | G10: 2.7673245 | H10: 1.1103475 | I10: 2.034323
A11: 2000.III | B11: 1241308 | C11: 7809823 | D11: 497360 | E11: 9548491 | F11: 4.141295 | G11: 1.2475773 | H11: 19.881025 | I11: 2.4470694
A12: 2000.IV | B12: 1241168 | C12: 7933267 | D12: 548483 | E12: 9722918 | F12: -0.011278426 | G12: 1.5806248 | H12: 10.278872 | I12: 1.8267494
A13: 2001.I | B13: 1255388 | C13: 7952018 | D13: 491957 | E13: 9699363 | F13: 1.145695 | G13: 0.23635912 | H13: -10.30588 | I13: -0.24226266 | J13: 3.036884 | K13: 5.9438749 | L13: 19.89535 | M13: 6.1828302
A14: 2001.II | B14: 1232212 | C14: 8044135 | D14: 526066 | E14: 9802413 | F14: -1.8461225 | G14: 1.1584104 | H14: 6.9333295 | I14: 1.0624409 | J14: 3.3781732 | K14: 4.2852291 | L14: 26.800168 | M14: 5.1714334
A15: 2001.III | B15: 1207624 | C15: 8136380 | D15: 465479 | E15: 9809483 | F15: -1.9954359 | G15: 1.1467361 | H15: -11.516996 | I15: 0.072125098 | J15: -2.7135892 | K15: 4.1813624 | L15: -6.410045 | M15: 2.7333324
A16: 2001.IV | B16: 1197778 | C16: 8244031 | D16: 488295 | E16: 9930104 | F16: -0.81532 | G16: 1.3230823 | H16: 4.9016175 | I16: 1.2296367 | J16: -3.4959006 | K16: 3.917226 | L16: -10.97354 | M16: 2.1309035
A17: 2002.I | B17: 1196035 | C17: 8307126 | D17: 560405 | E17: 10063566 | F17: -0.14551945 | G17: 0.76534162 | H17: 14.767712 | I17: 1.3440141 | J17: -4.727861 | K17: 4.4656338 | L17: 13.913411 | M17: 3.7549167
A18: 2002.II | B18: 1206414 | C18: 8426631 | D18: 572773 | E18: 10205818 | F18: 0.86778397 | G18: 1.4385842 | H18: 2.2069753 | I18: 1.4135347 | J18: -2.0936332 | K18: 4.7549674 | L18: 8.8785438 | M18: 4.1153642
A19: 2002.III | B19: 1189068 | C19: 8526636 | D19: 558504 | E19: 10274208 | F19: -1.4378149 | G19: 1.1867732 | H19: -2.4912138 | I19: 0.67010797 | J19: -1.536571 | K19: 4.7964328 | L19: 19.98479 | M19: 4.7375076
A20: 2002.IV | B20: 1153055 | C20: 8609583 | D20: 542764 | E20: 10305402 | F20: -3.0286746 | G20: 0.97279865 | H20: -2.818243 | I20: 0.30361464 | J20: -3.7338305 | K20: 4.4341415 | L20: 11.154937 | M20: 3.7793965
A21: 2003.I | B21: 1157573 | C21: 8712290 | D21: 570225 | E21: 10440088 | F21: 0.39182866 | G21: 1.1929381 | H21: 5.0594734 | I21: 1.3069456 | J21: -3.2157922 | K21: 4.8773065 | L21: 1.7523041 | M21: 3.7414372
A22: 2003.II | B22: 1071527 | C22: 8650931 | D22: 518333 | E22: 10240791 | F22: -7.4333109 | G22: -0.70428096 | H22: -9.1002674 | I22: -1.908959 | J22: -11.180822 | K22: 2.6617992 | L22: -9.504638 | M22: 0.34267709
A23: 2003.III | B23: 1265059 | C23: 8695286 | D23: 504036 | E23: 10464381 | F23: 18.061327 | G23: 0.51271938 | H23: -2.7582654 | I23: 2.1833274 | J23: 6.3908036 | K23: 1.9779195 | L23: -9.7524816 | M23: 1.8509748
A24: 2003.IV | B24: 1483081 | C24: 8827736 | D24: 505185 | E24: 10816002 | F24: 17.234137 | G24: 1.5232391 | H24: 0.22795991 | I24: 3.3601701 | J24: 28.621878 | K24: 2.5338393 | L24: -6.9236353 | M24: 4.954683
... A89: 2020.I | B89: 1666953 | C89: 15475006 | D89: 381089 | E89: 17523048 | F89: 2.8241349 | G89: -1.7128069 | H89: -28.704312 | I89: -2.1079006 | J89: 1.9188429 | K89: -1.7531735 | L89: -33.260889 | M89: -2.4206006
A91: (*) Suma del Valor Agregado de Extracción de petróleo, gas natural y del Valor Agregado de la Fabricación de productos de la refinación petróleo
A92: (**) Otros elementos del PIB incluye: otros impuestos sobre productos, subsidios sobre productos, derechos arancelarios, Impuesto al Valor Agregado (IVA)
A93: Elaboración: BANCO CENTRAL DEL ECUADOR

Sheet oilGDPnominal
A1: Menú Principal
A3: VALOR AGREGADO BRUTO PETROLERO (*) Y NO PETROLERO
B5: Miles de US dólares | F5: Deflactores implícitos, 2007 = 100
F6: Nivel | J6: Tasas de variación t/t-1 | N6: Tasas de variación t/t-4
A7: Industrias | B7: VALOR AGREGADO PETROLERO | C7: VALOR AGREGADO NO PETROLERO | D7: OTROS ELEMENTOS DEL PIB (**) | E7: P.I.B. | F7: VALOR AGREGADO PETROLERO | G7: VALOR AGREGADO NO PETROLERO | H7: OTROS ELEMENTOS DEL PIB (**) | I7: P.I.B. | J7: VALOR AGREGADO PETROLERO | K7: VALOR AGREGADO NO PETROLERO | L7: OTROS ELEMENTOS DEL PIB (**) | M7: P.I.B. | N7: VALOR AGREGADO PETROLERO | O7: VALOR AGREGADO NO PETROLERO | P7: OTROS ELEMENTOS DEL PIB | Q7: P.I.B.
A8: Trimestres
A10: 2000.I | B10: 332388 | C10: 3290847 | D10: 195891 | E10: 3819126 | F10: 27.280987 | G10: 43.843598 | H10: 47.740799 | I10: 41.809509
A11: 2000.II | B11: 369840 | C11: 3806141 | D11: 226498 | E11: 4402479 | F11: 31.028251 | G11: 49.343315 | H11: 54.593881 | I11: 47.234801 | J11: 13.735809 | K11: 12.543944 | L11: 14.35477 | M11: 12.976215
A12: 2000.III | B12: 460321 | C12: 4150331 | D12: 296001 | E12: 4906653 | F12: 37.083544 | G12: 53.142446 | H12: 59.514436 | I12: 51.386685 | J12: 19.515418 | K12: 7.6993845 | L12: 9.0130168 | M12: 8.7898838
A13: 2000.IV | B13: 462506 | C13: 4400253 | D13: 327584 | E13: 5190343 | F13: 37.263771 | G13: 55.465838 | H13: 59.725461 | I13: 53.382565 | J13: 0.486002 | K13: 4.3720067 | L13: 0.35457738 | M13: 3.8840406
A14: 2001.I | B14: 336056 | C14: 5130098 | D14: 437928 | E14: 5904082 | F14: 26.769094 | G14: 64.513159 | H14: 89.017536 | I14: 60.870822 | J14: -28.163216 | K14: 16.31152 | L14: 49.044536 | M14: 14.027534 | N14: -1.8763712 | O14: 47.143851 | P14: 86.46009 | Q14: 45.590855
A15: 2001.II | B15: 327311 | C15: 5256978 | D15: 485331 | E15: 6069620 | F15: 26.56288 | G15: 65.351688 | H15: 92.256675 | I15: 61.919652 | J15: -0.77034388 | K15: 1.29978 | L15: 3.638765 | M15: 1.7230418 | N15: -14.391307 | O15: 32.442841 | P15: 68.987209 | Q15: 31.08905
A16: 2001.III | B16: 322417 | C16: 5336981 | D16: 500211 | E16: 6159609 | F16: 26.698459 | G16: 65.594048 | H16: 107.46156 | I16: 62.792392 | J16: 0.51040666 | K16: 0.37085509 | L16: 16.481069 | M16: 1.4094717 | N16: -28.004564 | O16: 23.430614 | P16: 80.563856 | Q16: 22.195841
A17: 2001.IV | B17: 286737 | C17: 5535621 | D17: 512655 | E17: 6335013 | F17: 23.939077 | G17: 67.147018 | H17: 104.98879 | I17: 63.796039 | J17: -10.33536 | K17: 2.3675476 | L17: -2.3010773 | M17: 1.5983576 | N17: -35.757771 | O17: 21.060135 | P17: 75.785646 | Q17: 19.507257
A18: 2002.I | B18: 340321 | C18: 5858861 | D18: 538369 | E18: 6737551 | F18: 28.4541 | G18: 70.528135 | H18: 96.067844 | I18: 66.949936 | J18: 18.860473 | K18: 5.035393 | L18: -8.4970442 | M18: 4.9437196 | N18: 6.2945944 | O18: 9.3236416 | P18: 7.9201335 | Q18: 9.9869095
A19: 2002.II | B19: 394787 | C19: 6100775 | D19: 591065 | E19: 7086627 | F19: 32.724007 | G19: 72.398744 | H19: 103.19359 | I19: 69.437129 | J19: 15.006296 | K19: 2.6522882 | L19: 7.4174065 | M19: 3.7150041 | N19: 23.194497 | O19: 10.783281 | P19: 11.854873 | Q19: 12.140697
A20: 2002.III | B20: 416026 | C20: 6290885 | D20: 587221 | E20: 7294132 | F20: 34.98757 | G20: 73.779214 | H20: 105.14177 | I20: 70.994592 | J20: 6.9171335 | K20: 1.9067593 | L20: 1.8878938 | M20: 2.2429824 | N20: 31.047151 | O20: 12.478519 | P20: -2.1587156 | Q20: 13.06241
A21: 2002.IV | B21: 399758 | C21: 6438429 | D21: 592448 | E21: 7430635 | F21: 34.669465 | G21: 74.782124 | H21: 109.15389 | I21: 72.104271 | J21: -0.90919451 | K21: 1.3593393 | L21: 3.8159095 | M21: 1.5630481 | N21: 44.823732 | O21: 11.370729 | P21: 3.9671845 | Q21: 13.023116
A22: 2003.I | B22: 539520 | C22: 6906805 | D22: 565104 | E22: 8011429 | F22: 46.60786 | G22: 79.276574 | H22: 99.101933 | I22: 76.737179 | J22: 34.434897 | K22: 6.0100594 | L22: -9.2089739 | M22: 6.4252889 | N22: 63.800152 | O22: 12.404183 | P22: 3.1582781 | Q22: 14.618749
A23: 2003.II | B23: 440959 | C23: 6963355 | D23: 560764 | E23: 7965078 | F23: 41.152393 | G23: 80.49255 | H23: 108.18605 | I23: 77.777957 | J23: -11.705036 | K23: 1.5338412 | L23: 9.1664375 | M23: 1.3562891 | N23: 25.755972 | O23: 11.179485 | P23: 4.8379596 | Q23: 12.012058
A24: 2003.III | B24: 509102 | C24: 7045127 | D24: 566236 | E24: 8120465 | F24: 40.24334 | G24: 81.022372 | H24: 112.34039 | I24: 77.601007 | J24: -2.2089903 | K24: 0.65822476 | L24: 3.8399942 | M24: -0.22750676 | N24: 15.021822 | O24: 9.8173432 | P24: 6.8465812 | Q24: 9.305519
A25: 2003.IV | B25: 587169 | C25: 7179216 | D25: 569501 | E25: 8335886 | F25: 39.591162 | G25: 81.325676 | H25: 112.73118 | I25: 77.069938 | J25: -1.6205874 | K25: 0.37434587 | L25: 0.3478618 | M25: -0.68435841 | N25: 14.196057 | O25: 8.7501562 | P25: 3.2772917 | Q25: 6.8867856
... A90: 2020.I | B90: 1432939 | C90: 22867309 | D90: 1578350 | E90: 25878598 | F90: 85.961572 | G90: 147.76931 | H90: 414.16834 | I90: 147.6832 | J90: -14.425138 | K90: -0.28577173 | L90: 19.232542 | M90: -1.4238949 | N90: -15.112466 | O90: -0.0026269547 | P90: 29.545197 | Q90: -0.88672862
A92: (*) Suma del Valor Agregado de Extracción de petróleo, gas natural y del Valor Agregado de la Fabricación de productos de la refinación petróleo
A93: (**) Otros elementos del PIB incluye: otros impuestos sobre productos, subsidios sobre productos, derechos arancelarios, Impuesto al Valor Agregado (IVA)
A94: Elaboración: BANCO CENTRAL DEL ECUADOR

Sheet worldGDP
A1: Subject | B1: Measure | C1: Period | D1: Australia | E1: Austria | F1: Belgium | G1: Canada | H1: Chile | I1: Colombia | J1: Czech Republic | K1: Denmark | L1: Estonia | M1: Finland | N1: France | O1: Germany | P1: Greece | Q1: Hungary | R1: Iceland | S1: Ireland | T1: Israel | U1: Italy | V1: Japan | W1: Korea | X1: Latvia | Y1: Lithuania | Z1: Luxembourg | AA1: Mexico | AB1: Netherlands | AC1: New Zealand | AD1: Norway | AE1: Poland | AF1: Portugal | AG1: Slovak Republic | AH1: Slovenia | AI1: Spain | AJ1: Sweden | AK1: Switzerland | AL1: Turkey | AM1: United Kingdom | AN1: United States | AO1: Euro area (19 countries) | AP1: European Union – 27 countries (from 01/02/2020) | AQ1: G7 | AR1: NAFTA | AS1: OECD - Europe | AT1: G20 | AU1: OECD - Total | AV1: Argentina | AW1: Brazil | AX1: Bulgaria | AY1: China (People's Republic of) | AZ1: India | BA1: Indonesia | BB1: Romania | BC1: Russia | BD1: Saudi Arabia | BE1: South Africa
D2: Percentage | E2: Percentage | F2: Percentage | G2: Percentage | H2: Percentage | I2: Percentage | J2: Percentage | K2: Percentage | L2: Percentage | M2: Percentage | N2: Percentage | O2: Percentage | P2: Percentage | Q2: Percentage | R2: Percentage | S2: Percentage | T2: Percentage | U2: Percentage | V2: Percentage | W2: Percentage | X2: Percentage | Y2: Percentage | Z2: Percentage | AA2: Percentage | AB2: Percentage | AC2: Percentage | AD2: Percentage | AE2: Percentage | AF2: Percentage | AG2: Percentage | AH2: Percentage | AI2: Percentage | AJ2: Percentage | AK2: Percentage | AL2: Percentage | AM2: Percentage | AN2: Percentage | AO2: Percentage | AP2: Percentage | AQ2: Percentage | AR2: Percentage | AS2: Percentage | AT2: Percentage | AU2: Percentage | AV2: Percentage | AW2: Percentage | AX2: Percentage | AY2: Percentage | AZ2: Percentage | BA2: Percentage | BB2: Percentage | BC2: Percentage | BD2: Percentage | BE2: Percentage
A3: B1_GE: Gross domestic product - expenditure approach | B3: GPSA: Growth rate compared to previous quarter, seasonally adjusted | C3: Q2-1947 | D3: .. | E3: .. | F3: .. | G3: .. | H3: .. | I3: .. | J3: .. | K3: .. | L3: .. | M3: .. | N3: .. | O3: .. | P3: .. | Q3: .. | R3: .. | S3: .. | T3: .. | U3: .. | V3: .. | W3: .. | X3: .. | Y3: .. | Z3: .. | AA3: .. | AB3: .. | AC3: .. | AD3: .. | AE3: .. | AF3: .. | AG3: .. | AH3: .. | AI3: .. | AJ3: .. | AK3: .. | AL3: .. | AM3: .. | AN3: -0.266691 | AO3: .. | AP3: .. | AQ3: .. | AR3: .. | AS3: .. | AT3: .. | AU3: .. | AV3: .. | AW3: .. | AX3: .. | AY3: .. | AZ3: .. | BA3: .. | BB3: .. | BC3: .. | BD3: .. | BE3: ..
C4: Q3-1947 | D4: .. | E4: .. | F4: .. | G4: .. | H4: .. | I4: .. | J4: .. | K4: .. | L4: .. | M4: .. | N4: .. | O4: .. | P4: .. | Q4: .. | R4: .. | S4: .. | T4: .. | U4: .. | V4: .. | W4: .. | X4: .. | Y4: .. | Z4: .. | AA4: .. | AB4: .. | AC4: .. | AD4: .. | AE4: .. | AF4: .. | AG4: .. | AH4: .. | AI4: .. | AJ4: .. | AK4: .. | AL4: .. | AM4: .. | AN4: -0.206496 | AO4: .. | AP4: .. | AQ4: .. | AR4: .. | AS4: .. | AT4: .. | AU4: .. | AV4: .. | AW4: .. | AX4: .. | AY4: .. | AZ4: .. | BA4: .. | BB4: .. | BC4: .. | BD4: .. | BE4: ..
C5: Q4-1947 | D5: .. | E5: .. | F5: .. | G5: .. | H5: .. | I5: .. | J5: .. | K5: .. | L5: .. | M5: .. | N5: .. | O5: .. | P5: .. | Q5: .. | R5: .. | S5: .. | T5: .. | U5: .. | V5: .. | W5: .. | X5: .. | Y5: .. | Z5: .. | AA5: .. | AB5: .. | AC5: .. | AD5: .. | AE5: .. | AF5: .. | AG5: .. | AH5: .. | AI5: .. | AJ5: .. | AK5: .. | AL5: .. | AM5: .. | AN5: 1.564208 | AO5: .. | AP5: .. | AQ5: .. | AR5: .. | AS5: .. | AT5: .. | AU5: .. | AV5: .. | AW5: .. | AX5: .. | AY5: .. | AZ5: .. | BA5: .. | BB5: .. | BC5: .. | BD5: .. | BE5: ..
C6: Q1-1948 | D6: .. | E6: .. | F6: .. | G6: .. | H6: .. | I6: .. | J6: .. | K6: .. | L6: .. | M6: .. | N6: .. | O6: .. | P6: .. | Q6: .. | R6: .. | S6: .. | T6: .. | U6: .. | V6: .. | W6: .. | X6: .. | Y6: .. | Z6: .. | AA6: .. | AB6: .. | AC6: .. | AD6: .. | AE6: .. | AF6: .. | AG6: .. | AH6: .. | AI6: .. | AJ6: .. | AK6: .. | AL6: .. | AM6: .. | AN6: 1.504256 | AO6: .. | AP6: .. | AQ6: .. | AR6: .. | AS6: .. | AT6: .. | AU6: .. | AV6: .. | AW6: .. | AX6: .. | AY6: .. | AZ6: .. | BA6: .. | BB6: .. | BC6: .. | BD6: .. | BE6: ..
C7: Q2-1948 | D7: .. | E7: .. | F7: .. | G7: .. | H7: .. | I7: .. | J7: .. | K7: .. | L7: .. | M7: .. | N7: .. | O7: .. | P7: .. | Q7: .. | R7: .. | S7: .. | T7: .. | U7: .. | V7: .. | W7: .. | X7: .. | Y7: .. | Z7: .. | AA7: .. | AB7: .. | AC7: .. | AD7: .. | AE7: .. | AF7: .. | AG7: .. | AH7: .. | AI7: .. | AJ7: .. | AK7: .. | AL7: .. | AM7: .. | AN7: 1.650658 | AO7: .. | AP7: .. | AQ7: .. | AR7: .. | AS7: .. | AT7: .. | AU7: .. | AV7: .. | AW7: .. | AX7: .. | AY7: .. | AZ7: .. | BA7: .. | BB7: .. | BC7: .. | BD7: .. | BE7: ..
C8: Q3-1948 | D8: .. | E8: .. | F8: .. | G8: .. | H8: .. | I8: .. | J8: .. | K8: .. | L8: .. | M8: .. | N8: .. | O8: .. | P8: .. | Q8: .. | R8: .. | S8: .. | T8: .. | U8: .. | V8: .. | W8: .. | X8: .. | Y8: .. | Z8: .. | AA8: .. | AB8: .. | AC8: .. | AD8: .. | AE8: .. | AF8: .. | AG8: .. | AH8: .. | AI8: .. | AJ8: .. | AK8: .. | AL8: .. | AM8: .. | AN8: 0.572897 | AO8: .. | AP8: .. | AQ8: .. | AR8: .. | AS8: .. | AT8: .. | AU8: .. | AV8: .. | AW8: .. | AX8: .. | AY8: .. | AZ8: .. | BA8: .. | BB8: .. | BC8: .. | BD8: .. | BE8: ..
C9: Q4-1948 | D9: .. | E9: .. | F9: .. | G9: .. | H9: .. | I9: .. | J9: .. | K9: .. | L9: .. | M9: .. | N9: .. | O9: .. | P9: .. | Q9: .. | R9: .. | S9: .. | T9: .. | U9: .. | V9: .. | W9: .. | X9: .. | Y9: .. | Z9: .. | AA9: .. | AB9: .. | AC9: .. | AD9: .. | AE9: .. | AF9: .. | AG9: .. | AH9: .. | AI9: .. | AJ9: .. | AK9: .. | AL9: .. | AM9: .. | AN9: 0.111742 | AO9: .. | AP9: .. | AQ9: .. | AR9: .. | AS9: .. | AT9: .. | AU9: .. | AV9: .. | AW9: .. | AX9: .. | AY9: .. | AZ9: .. | BA9: .. | BB9: .. | BC9: .. | BD9: .. | BE9: ..
C10: Q1-1949 | D10: .. | E10: .. | F10: .. | G10: .. | H10: .. | I10: .. | J10: .. | K10: .. | L10: .. | M10: .. | N10: .. | O10: .. | P10: .. | Q10: .. | R10: .. | S10: .. | T10: .. | U10: .. | V10: .. | W10: .. | X10: .. | Y10: .. | Z10: .. | AA10: .. | AB10: .. | AC10: .. | AD10: .. | AE10: .. | AF10: .. | AG10: .. | AH10: .. | AI10: .. | AJ10: .. | AK10: .. | AL10: .. | AM10: .. | AN10: -1.377951 | AO10: .. | AP10: .. | AQ10: .. | AR10: .. | AS10: .. | AT10: .. | AU10: .. | AV10: .. | AW10: .. | AX10: .. | AY10: .. | AZ10: .. | BA10: .. | BB10: .. | BC10: .. | BD10: .. | BE10: ..
C11: Q2-1949 | D11: .. | E11: .. | F11: .. | G11: .. | H11: .. | I11: .. | J11: .. | K11: .. | L11: .. | M11: .. | N11: .. | O11: .. | P11: .. | Q11: .. | R11: .. | S11: .. | T11: .. | U11: .. | V11: .. | W11: .. | X11: .. | Y11: .. | Z11: .. | AA11: .. | AB11: .. | AC11: .. | AD11: .. | AE11: .. | AF11: .. | AG11: .. | AH11: .. | AI11: .. | AJ11: .. | AK11: .. | AL11: .. | AM11: .. | AN11: -0.341097 | AO11: .. | AP11: .. | AQ11: .. | AR11: .. | AS11: .. | AT11: .. | AU11: .. | AV11: .. | AW11: .. | AX11: .. | AY11: .. | AZ11: .. | BA11: .. | BB11: .. | BC11: .. | BD11: .. | BE11: ..
C12: Q3-1949 | D12: .. | E12: .. | F12: .. | G12: .. | H12: .. | I12: .. | J12: .. | K12: .. | L12: .. | M12: .. | N12: .. | O12: .. | P12: .. | Q12: .. | R12: .. | S12: .. | T12: .. | U12: .. | V12: .. | W12: .. | X12: .. | Y12: .. | Z12: .. | AA12: .. | AB12: .. | AC12: .. | AD12: .. | AE12: .. | AF12: .. | AG12: .. | AH12: .. | AI12: .. | AJ12: .. | AK12: .. | AL12: .. | AM12: .. | AN12: 1.032415 | AO12: .. | AP12: .. | AQ12: .. | AR12: .. | AS12: .. | AT12: .. | AU12: .. | AV12: .. | AW12: .. | AX12: .. | AY12: .. | AZ12: .. | BA12: .. | BB12: .. | BC12: .. | BD12: .. | BE12: ..
C13: Q4-1949 | D13: .. | E13: .. | F13: .. | G13: .. | H13: .. | I13: .. | J13: .. | K13: .. | L13: .. | M13: .. | N13: .. | O13: .. | P13: .. | Q13: .. | R13: .. | S13: .. | T13: .. | U13: .. | V13: .. | W13: .. | X13: .. | Y13: .. | Z13: .. | AA13: .. | AB13: .. | AC13: .. | AD13: .. | AE13: .. | AF13: .. | AG13: .. | AH13: .. | AI13: .. | AJ13: .. | AK13: .. | AL13: .. | AM13: .. | AN13: -0.839275 | AO13: .. | AP13: .. | AQ13: .. | AR13: .. | AS13: .. | AT13: .. | AU13: .. | AV13: .. | AW13: .. | AX13: .. | AY13: .. | AZ13: .. | BA13: .. | BB13: .. | BC13: .. | BD13: .. | BE13: ..
C14: Q1-1950 | D14: .. | E14: .. | F14: .. | G14: .. | H14: .. | I14: .. | J14: .. | K14: .. | L14: .. | M14: .. | N14: .. | O14: .. | P14: .. | Q14: .. | R14: .. | S14: .. | T14: .. | U14: .. | V14: .. | W14: .. | X14: .. | Y14: .. | Z14: .. | AA14: .. | AB14: .. | AC14: .. | AD14: .. | AE14: .. | AF14: .. | AG14: .. | AH14: .. | AI14: .. | AJ14: .. | AK14: .. | AL14: .. | AM14: .. | AN14: 3.930121 | AO14: .. | AP14: .. | AQ14: .. | AR14: .. | AS14: .. | AT14: .. | AU14: .. | AV14: .. | AW14: .. | AX14: .. | AY14: .. | AZ14: .. | BA14: .. | BB14: .. | BC14: .. | BD14: .. | BE14: ..
C15: Q2-1950 | D15: .. | E15: .. | F15: .. | G15: .. | H15: .. | I15: .. | J15: .. | K15: .. | L15: .. | M15: .. | N15: .. | O15: .. | P15: .. | Q15: .. | R15: .. | S15: .. | T15: .. | U15: .. | V15: .. | W15: .. | X15: .. | Y15: .. | Z15: .. | AA15: .. | AB15: .. | AC15: .. | AD15: .. | AE15: .. | AF15: .. | AG15: .. | AH15: .. | AI15: .. | AJ15: .. | AK15: .. | AL15: .. | AM15: .. | AN15: 3.049835 | AO15: .. | AP15: .. | AQ15: .. | AR15: .. | AS15: .. | AT15: .. | AU15: .. | AV15: .. | AW15: .. | AX15: .. | AY15: .. | AZ15: .. | BA15: .. | BB15: .. | BC15: .. | BD15: .. | BE15: ..
... C34: Q1-1955 | D34: .. | E34: .. | F34: .. | G34: .. | H34: .. | I34: .. | J34: .. | K34: .. | L34: .. | M34: .. | N34: .. | O34: .. | P34: .. | Q34: .. | R34: .. | S34: .. | T34: .. | U34: .. | V34: .. | W34: .. | X34: .. | Y34: .. | Z34: .. | AA34: .. | AB34: .. | AC34: .. | AD34: .. | AE34: .. | AF34: .. | AG34: .. | AH34: .. | AI34: .. | AJ34: .. | AK34: .. | AL34: .. | AM34: .. | AN34: 2.856249 | AO34: .. | AP34: .. | AQ34: .. | AR34: .. | AS34: .. | AT34: .. | AU34: .. | AV34: .. | AW34: .. | AX34: .. | AY34: .. | AZ34: .. | BA34: .. | BB34: .. | BC34: .. | BD34: .. | BE34: ..
C35: Q2-1955 | D35: .. | E35: .. | F35: .. | G35: .. | H35: .. | I35: .. | J35: .. | K35: .. | L35: .. | M35: .. | N35: .. | O35: .. | P35: .. | Q35: .. | R35: .. | S35: .. | T35: .. | U35: .. | V35: .. | W35: .. | X35: .. | Y35: .. | Z35: .. | AA35: .. | AB35: .. | AC35: .. | AD35: .. | AE35: .. | AF35: .. | AG35: .. | AH35: .. | AI35: .. | AJ35: .. | AK35: .. | AL35: .. | AM35: 0.065066 | AN35: 1.627179 | AO35: .. | AP35: .. | AQ35: .. | AR35: .. | AS35: .. | AT35: .. | AU35: .. | AV35: .. | AW35: .. | AX35: .. | AY35: .. | AZ35: .. | BA35: .. | BB35: .. | BC35: .. | BD35: .. | BE35: ..
C36: Q3-1955 | D36: .. | E36: .. | F36: .. | G36: .. | H36: .. | I36: .. | J36: .. | K36: .. | L36: .. | M36: .. | N36: .. | O36: .. | P36: .. | Q36: .. | R36: .. | S36: .. | T36: .. | U36: .. | V36: .. | W36: .. | X36: .. | Y36: .. | Z36: .. | AA36: .. | AB36: .. | AC36: .. | AD36: .. | AE36: .. | AF36: .. | AG36: .. | AH36: .. | AI36: .. | AJ36: .. | AK36: .. | AL36: .. | AM36: 2.022856 | AN36: 1.350478 | AO36: .. | AP36: .. | AQ36: .. | AR36: .. | AS36: .. | AT36: .. | AU36: .. | AV36: .. | AW36: .. | AX36: .. | AY36: .. | AZ36: .. | BA36: .. | BB36: .. | BC36: .. | BD36: .. | BE36: ..
C37: Q4-1955 | D37: .. | E37: .. | F37: .. | G37: .. | H37: .. | I37: .. | J37: .. | K37: .. | L37: .. | M37: .. | N37: .. | O37: .. | P37: .. | Q37: .. | R37: .. | S37: .. | T37: .. | U37: .. | V37: .. | W37: .. | X37: .. | Y37: .. | Z37: .. | AA37: .. | AB37: .. | AC37: .. | AD37: .. | AE37: .. | AF37: .. | AG37: .. | AH37: .. | AI37: .. | AJ37: .. | AK37: .. | AL37: .. | AM37: -0.523844 | AN37: 0.600325 | AO37: .. | AP37: .. | AQ37: .. | AR37: .. | AS37: .. | AT37: .. | AU37: .. | AV37: .. | AW37: .. | AX37: .. | AY37: .. | AZ37: .. | BA37: .. | BB37: .. | BC37: .. | BD37: .. | BE37: ..
C38: Q1-1956 | D38: .. | E38: .. | F38: .. | G38: .. | H38: .. | I38: .. | J38: .. | K38: .. | L38: .. | M38: .. | N38: .. | O38: .. | P38: .. | Q38: .. | R38: .. | S38: .. | T38: .. | U38: .. | V38: .. | W38: .. | X38: .. | Y38: .. | Z38: .. | AA38: .. | AB38: .. | AC38: .. | AD38: .. | AE38: .. | AF38: .. | AG38: .. | AH38: .. | AI38: .. | AJ38: .. | AK38: .. | AL38: .. | AM38: 1.172568 | AN38: -0.388406 | AO38: .. | AP38: .. | AQ38: .. | AR38: .. | AS38: .. | AT38: .. | AU38: .. | AV38: .. | AW38: .. | AX38: .. | AY38: .. | AZ38: .. | BA38: .. | BB38: .. | BC38: .. | BD38: .. | BE38: ..
C39: Q2-1956 | D39: .. | E39: .. | F39: .. | G39: .. | H39: .. | I39: .. | J39: .. | K39: .. | L39: .. | M39: .. | N39: .. | O39: .. | P39: .. | Q39: .. | R39: .. | S39: .. | T39: .. | U39: .. | V39: .. | W39: .. | X39: .. | Y39: .. | Z39: .. | AA39: .. | AB39: .. | AC39: .. | AD39: .. | AE39: .. | AF39: .. | AG39: .. | AH39: .. | AI39: .. | AJ39: .. | AK39: .. | AL39: .. | AM39: -0.216875 | AN39: 0.826333 | AO39: .. | AP39: .. | AQ39: .. | AR39: .. | AS39: .. | AT39: .. | AU39: .. | AV39: .. | AW39: .. | AX39: .. | AY39: .. | AZ39: .. | BA39: .. | BB39: .. | BC39: .. | BD39: .. | BE39: ..
C40: Q3-1956 | D40: .. | E40: .. | F40: .. | G40: .. | H40: .. | I40: .. | J40: .. | K40: .. | L40: .. | M40: .. | N40: .. | O40: .. | P40: .. | Q40: .. | R40: .. | S40: .. | T40: .. | U40: .. | V40: .. | W40: .. | X40: .. | Y40: .. | Z40: .. | AA40: .. | AB40: .. | AC40: .. | AD40: .. | AE40: .. | AF40: .. | AG40: .. | AH40: .. | AI40: .. | AJ40: .. | AK40: .. | AL40: .. | AM40: -0.116497 | AN40: -0.089833 | AO40: .. | AP40: .. | AQ40: .. | AR40: .. | AS40: .. | AT40: .. | AU40: .. | AV40: .. | AW40: .. | AX40: .. | AY40: .. | AZ40: .. | BA40: .. | BB40: .. | BC40: .. | BD40: .. | BE40: ..
C41: Q4-1956 | D41: .. | E41: .. | F41: .. | G41: .. | H41: .. | I41: .. | J41: .. | K41: .. | L41: .. | M41: .. | N41: .. | O41: .. | P41: .. | Q41: .. | R41: .. | S41: .. | T41: .. | U41: .. | V41: .. | W41: .. | X41: .. | Y41: .. | Z41: .. | AA41: .. | AB41: .. | AC41: .. | AD41: .. | AE41: .. | AF41: .. | AG41: .. | AH41: .. | AI41: .. | AJ41: .. | AK41: .. | AL41: .. | AM41: 0.469144 | AN41: 1.645929 | AO41: .. | AP41: .. | AQ41: .. | AR41: .. | AS41: .. | AT41: .. | AU41: .. | AV41: .. | AW41: .. | AX41: .. | AY41: .. | AZ41: .. | BA41: .. | BB41: .. | BC41: .. | BD41: .. | BE41: ..
