Workbook

Sheet mixed frequency
B2: Tabla.- Horas de trabajo promedio a la semana por personas ocupadas, a nivel nacional
B3: Nota.- Las horas corresponden a las horas efectivamente trabajadas en la semana de referencia.
C5: Total | D5: Hombre | E5: Mujer | F5: Tasa desempleo | G5: Total horas trabajadas
B6: dic-07 | C6: 41.85803 | D6: 44.538657 | E6: 37.778383 | F6: 4.9983546 | G6: =C6*(1-F6/100) -> 39.765817
B7: jun-08 | C7: 41.98648 | D7: 44.787558 | E7: 37.798633 | F7: 5.2227055 | G7: =C7*(1-F7/100) -> 39.793649
B8: dic-08 | C8: 42.365512 | D8: 45.035097 | E8: 38.271032 | F8: 5.951463 | G8: =C8*(1-F8/100) -> 39.844144
B9: dic-09 | C9: 41.644333 | D9: 43.937111 | E9: 38.146651 | F9: 6.47131 | G9: =C9*(1-F9/100) -> 38.949399
B10: jun-10 | C10: 40.751967 | D10: 43.315613 | E10: 36.875628 | F10: 6.203129 | G10: =C10*(1-F10/100) -> 38.22407
B11: dic-10 | C11: 41.623721 | D11: 43.735932 | E11: 38.297797 | F11: 5.018858 | G11: =C11*(1-F11/100) -> 39.534685
B12: jun-11 | C12: 41.250911 | D12: 43.387299 | E12: 37.981625 | F12: 5.0231254 | G12: =C12*(1-F12/100) -> 39.178826
B13: dic-11 | C13: 41.117578 | D13: 43.488184 | E13: 37.413269 | F13: 4.2054597 | G13: =C13*(1-F13/100) -> 39.388395
B14: jun-12 | C14: 39.959031 | D14: 42.050248 | E14: 36.78869 | F14: 4.1126056 | G14: =C14*(1-F14/100) -> 38.315673
B15: dic-12 | C15: 40.617174 | D15: 42.493189 | E15: 37.737916 | F15: 4.121378 | G15: =C15*(1-F15/100) -> 38.943186
B16: jun-13 | C16: 39.454295 | D16: 41.852262 | E16: 35.910266 | F16: 3.913723 | G16: =C16*(1-F16/100) -> 37.910163
B17: dic-13 | C17: 40.609413 | D17: 42.807539 | E17: 37.149253 | F17: 4.1528209 | G17: =C17*(1-F17/100) -> 38.922977
... B57: dic-21 | C57: 35.086422 | D57: 37.897996 | E57: 31.244532 | F57: 4.14655 | G57: =C57*(1-F57/100) -> 33.631546

Sheet quarterly
B1: Total horas trabajadas
A2: 39417 | B2: ='mixed frequency'!G6 -> 39.765817
A3: 39508
A4: 39600 | B4: ='mixed frequency'!G7 -> 39.793649
A5: 39692
A6: 39783 | B6: ='mixed frequency'!G8 -> 39.844144
A7: 39873
A8: 39965
A9: 40057
A10: 40148 | B10: ='mixed frequency'!G9 -> 38.949399
A11: 40238
A12: 40330 | B12: ='mixed frequency'!G10 -> 38.22407
A13: 40422
A14: 40513 | B14: ='mixed frequency'!G11 -> 39.534685
A15: 40603
A16: 40695 | B16: ='mixed frequency'!G12 -> 39.178826
A17: 40787
A18: 40878 | B18: ='mixed frequency'!G13 -> 39.388395
A19: 40969
A20: 41061 | B20: ='mixed frequency'!G14 -> 38.315673
A21: 41153
A22: 41244 | B22: ='mixed frequency'!G15 -> 38.943186
A23: 41334
A24: 41426 | B24: ='mixed frequency'!G16 -> 37.910163
A25: 41518
A26: 41609 | B26: ='mixed frequency'!G17 -> 38.922977
A27: 41699 | B27: ='mixed frequency'!G18 -> 37.097129
A28: 41791 | B28: ='mixed frequency'!G19 -> 38.286171
A29: 41883 | B29: ='mixed frequency'!G20 -> 37.680588
A30: 41974 | B30: ='mixed frequency'!G21 -> 37.970763
A31: 42064 | B31: ='mixed frequency'!G22 -> 37.347193
A32: 42156 | B32: ='mixed frequency'!G23 -> 37.366302
A33: 42248 | B33: ='mixed frequency'!G24 -> 36.770738
A34: 42339 | B34: ='mixed frequency'!G25 -> 37.091328
A35: 42430 | B35: ='mixed frequency'!G26 -> 35.415562
A36: 42522 | B36: ='mixed frequency'!G27 -> 35.754432
A37: 42614 | B37: ='mixed frequency'!G28 -> 34.800694
... A50: 43800 | B50: ='mixed frequency'!G41 -> 36.164914
A51: 43891
A52: 43983
...
